<?xml version="1.0" ?>
<!-- =================================================================================== -->
<!-- |    This document was autogenerated by xacro from /home/vaibhav/husky/assets/husky_with_cameras.urdf.xacro | -->
<!-- |    EDITING THIS FILE BY HAND IS NOT RECOMMENDED                                 | -->
<!-- =================================================================================== -->
<!--
  Husky + 4 Intel RealSense D435 cameras (front / rear / left / right).

  Single source of truth for the camera mount + optical frames, shared between
  Isaac Sim and real hardware. Isaac attaches Camera sensor prims at the
  *_color_optical_frame defined here; on real hardware robot_state_publisher +
  realsense2_camera provide the same frames. The D435 .dae mesh gives the robot
  a visible camera body.

  Expand with:
    xacro husky_with_cameras.urdf.xacro is_sim:=false gazebo_controllers:=none \
          -o husky.urdf
-->
<robot name="husky">
  <material name="dark_grey">
    <color rgba="0.2 0.2 0.2 1.0"/>
  </material>
  <material name="medium_grey">
    <color rgba="0.6 0.6 0.6 1.0"/>
  </material>
  <material name="light_grey">
    <color rgba="0.8 0.8 0.8 1.0"/>
  </material>
  <material name="yellow">
    <color rgba="0.8 0.8 0.0 1.0"/>
  </material>
  <material name="black">
    <color rgba="0.15 0.15 0.15 1.0"/>
  </material>
  <material name="white">
    <color rgba="1.0 1.0 1.0 1.0"/>
  </material>
  <material name="red">
    <color rgba="1.0 0.0 0.0 1.0"/>
  </material>
  <!-- Base link is the center of the robot's bottom plate -->
  <link name="base_link">
    <visual>
      <origin rpy="0 0 0" xyz="0 0 0"/>
      <geometry>
        <mesh filename="/home/vaibhav/husky/husky_ws/install/husky_description/share/husky_description/meshes/base_link.dae"/>
      </geometry>
    </visual>
    <collision>
      <origin rpy="0 0 0" xyz="0.0 0 0.061875"/>
      <geometry>
        <box size="0.9874 0.5709 0.12375"/>
      </geometry>
    </collision>
    <collision>
      <origin rpy="0 0 0" xyz="0 0 0.17562499999999998"/>
      <geometry>
        <box size="0.7899200000000001 0.5709 0.10375"/>
      </geometry>
    </collision>
  </link>
  <!-- Base footprint is on the ground under the robot -->
  <link name="base_footprint"/>
  <joint name="base_footprint_joint" type="fixed">
    <origin rpy="0 0 0" xyz="0 0 -0.13228"/>
    <parent link="base_link"/>
    <child link="base_footprint"/>
  </joint>
  <!-- Inertial link stores the robot's inertial information -->
  <link name="inertial_link">
    <inertial>
      <mass value="46.034"/>
      <origin xyz="-0.00065 -0.085 0.062"/>
      <inertia ixx="0.6022" ixy="-0.02364" ixz="-0.1197" iyy="1.7386" iyz="-0.001544" izz="2.0296"/>
    </inertial>
  </link>
  <joint name="inertial_joint" type="fixed">
    <origin rpy="0 0 0" xyz="0 0 0"/>
    <parent link="base_link"/>
    <child link="inertial_link"/>
  </joint>
  <!-- IMU Link-->
  <!-- Can be modified with environment variables in /etc/ros/setup.bash -->
  <link name="imu_link"/>
  <joint name="imu_joint" type="fixed">
    <origin rpy="0 0 0" xyz="0 0 0"/>
    <parent link="base_link"/>
    <child link="imu_link"/>
  </joint>
  <!-- GPS Link-->
  <!-- Can be modified with environment variables in /etc/ros/setup.bash -->
  <link name="gps_link"/>
  <joint name="gps_joint" type="fixed">
    <origin rpy="0 0 0" xyz="0 0 0"/>
    <parent link="base_link"/>
    <child link="gps_link"/>
  </joint>
  <link name="front_left_wheel">
    <inertial>
      <mass value="2.637"/>
      <origin xyz="0 0 0"/>
      <inertia ixx="0.02467" ixy="0" ixz="0" iyy="0.04411" iyz="0" izz="0.02467"/>
    </inertial>
    <visual>
      <origin rpy="0 0 0" xyz="0 0 0"/>
      <geometry>
        <mesh filename="/home/vaibhav/husky/husky_ws/install/husky_description/share/husky_description/meshes/wheel.dae"/>
      </geometry>
    </visual>
    <collision>
      <origin rpy="1.570795 0 0" xyz="0 0 0"/>
      <geometry>
        <cylinder length="0.1143" radius="0.1651"/>
      </geometry>
    </collision>
  </link>
  <gazebo reference="front_left_wheel">
    <mu1 value="1.0"/>
    <mu2 value="0.5"/>
    <kp value="10000000.0"/>
    <kd value="1.0"/>
    <fdir1 value="1 0 0"/>
  </gazebo>
  <joint name="front_left_wheel_joint" type="continuous">
    <parent link="base_link"/>
    <child link="front_left_wheel"/>
    <origin rpy="0 0 0" xyz="0.256 0.2854 0.03282"/>
    <axis rpy="0 0 0" xyz="0 1 0"/>
  </joint>
  <link name="front_right_wheel">
    <inertial>
      <mass value="2.637"/>
      <origin xyz="0 0 0"/>
      <inertia ixx="0.02467" ixy="0" ixz="0" iyy="0.04411" iyz="0" izz="0.02467"/>
    </inertial>
    <visual>
      <origin rpy="0 0 0" xyz="0 0 0"/>
      <geometry>
        <mesh filename="/home/vaibhav/husky/husky_ws/install/husky_description/share/husky_description/meshes/wheel.dae"/>
      </geometry>
    </visual>
    <collision>
      <origin rpy="1.570795 0 0" xyz="0 0 0"/>
      <geometry>
        <cylinder length="0.1143" radius="0.1651"/>
      </geometry>
    </collision>
  </link>
  <gazebo reference="front_right_wheel">
    <mu1 value="1.0"/>
    <mu2 value="0.5"/>
    <kp value="10000000.0"/>
    <kd value="1.0"/>
    <fdir1 value="1 0 0"/>
  </gazebo>
  <joint name="front_right_wheel_joint" type="continuous">
    <parent link="base_link"/>
    <child link="front_right_wheel"/>
    <origin rpy="0 0 0" xyz="0.256 -0.2854 0.03282"/>
    <axis rpy="0 0 0" xyz="0 1 0"/>
  </joint>
  <link name="rear_left_wheel">
    <inertial>
      <mass value="2.637"/>
      <origin xyz="0 0 0"/>
      <inertia ixx="0.02467" ixy="0" ixz="0" iyy="0.04411" iyz="0" izz="0.02467"/>
    </inertial>
    <visual>
      <origin rpy="0 0 0" xyz="0 0 0"/>
      <geometry>
        <mesh filename="/home/vaibhav/husky/husky_ws/install/husky_description/share/husky_description/meshes/wheel.dae"/>
      </geometry>
    </visual>
    <collision>
      <origin rpy="1.570795 0 0" xyz="0 0 0"/>
      <geometry>
        <cylinder length="0.1143" radius="0.1651"/>
      </geometry>
    </collision>
  </link>
  <gazebo reference="rear_left_wheel">
    <mu1 value="1.0"/>
    <mu2 value="0.5"/>
    <kp value="10000000.0"/>
    <kd value="1.0"/>
    <fdir1 value="1 0 0"/>
  </gazebo>
  <joint name="rear_left_wheel_joint" type="continuous">
    <parent link="base_link"/>
    <child link="rear_left_wheel"/>
    <origin rpy="0 0 0" xyz="-0.256 0.2854 0.03282"/>
    <axis rpy="0 0 0" xyz="0 1 0"/>
  </joint>
  <link name="rear_right_wheel">
    <inertial>
      <mass value="2.637"/>
      <origin xyz="0 0 0"/>
      <inertia ixx="0.02467" ixy="0" ixz="0" iyy="0.04411" iyz="0" izz="0.02467"/>
    </inertial>
    <visual>
      <origin rpy="0 0 0" xyz="0 0 0"/>
      <geometry>
        <mesh filename="/home/vaibhav/husky/husky_ws/install/husky_description/share/husky_description/meshes/wheel.dae"/>
      </geometry>
    </visual>
    <collision>
      <origin rpy="1.570795 0 0" xyz="0 0 0"/>
      <geometry>
        <cylinder length="0.1143" radius="0.1651"/>
      </geometry>
    </collision>
  </link>
  <gazebo reference="rear_right_wheel">
    <mu1 value="1.0"/>
    <mu2 value="0.5"/>
    <kp value="10000000.0"/>
    <kd value="1.0"/>
    <fdir1 value="1 0 0"/>
  </gazebo>
  <joint name="rear_right_wheel_joint" type="continuous">
    <parent link="base_link"/>
    <child link="rear_right_wheel"/>
    <origin rpy="0 0 0" xyz="-0.256 -0.2854 0.03282"/>
    <axis rpy="0 0 0" xyz="0 1 0"/>
  </joint>
  <!-- Spawn Husky chassis -->
  <link name="top_chassis_link">
    <visual>
      <origin rpy="0 0 0" xyz="0 0 0"/>
      <geometry>
        <mesh filename="/home/vaibhav/husky/husky_ws/install/husky_description/share/husky_description/meshes/top_chassis.dae"/>
      </geometry>
    </visual>
  </link>
  <!-- Attach chassis to the robot -->
  <joint name="top_chassis_joint" type="fixed">
    <parent link="base_link"/>
    <child link="top_chassis_link"/>
  </joint>
  <!-- Spawn user rails -->
  <link name="user_rail_link">
    <visual>
      <geometry>
        <mesh filename="/home/vaibhav/husky/husky_ws/install/husky_description/share/husky_description/meshes/user_rail.dae"/>
      </geometry>
    </visual>
  </link>
  <!-- Attach user rails to base link -->
  <joint name="user_rail" type="fixed">
    <origin rpy="0 0 0" xyz="0.272 0 0.245"/>
    <parent link="base_link"/>
    <child link="user_rail_link"/>
  </joint>
  <!-- Spawn front bumper link -->
  <link name="front_bumper_link">
    <visual>
      <geometry>
        <mesh filename="/home/vaibhav/husky/husky_ws/install/husky_description/share/husky_description/meshes/bumper.dae"/>
      </geometry>
    </visual>
  </link>
  <!-- Attach front bumper -->
  <joint name="front_bumper" type="fixed">
    <origin rpy="0 0 0" xyz="0.48 0 0.091"/>
    <parent link="base_link"/>
    <child link="front_bumper_link"/>
  </joint>
  <!-- Spawn rear bumper link -->
  <link name="rear_bumper_link">
    <visual>
      <geometry>
        <mesh filename="/home/vaibhav/husky/husky_ws/install/husky_description/share/husky_description/meshes/bumper.dae"/>
      </geometry>
    </visual>
  </link>
  <!-- Attach rear bumper -->
  <joint name="rear_bumper" type="fixed">
    <origin rpy="0 0 3.14159" xyz="-0.48 0 0.091"/>
    <parent link="base_link"/>
    <child link="rear_bumper_link"/>
  </joint>
  <link name="top_plate_link">
    <visual>
      <origin rpy="0 0 0" xyz="0 0 0"/>
      <geometry>
        <mesh filename="/home/vaibhav/husky/husky_ws/install/husky_description/share/husky_description/meshes/top_plate.dae"/>
      </geometry>
    </visual>
    <collision>
      <origin rpy="0 0 0" xyz="0 0 0"/>
      <geometry>
        <mesh filename="/home/vaibhav/husky/husky_ws/install/husky_description/share/husky_description/meshes/top_plate.stl"/>
      </geometry>
    </collision>
  </link>
  <!-- Attach top plate -->
  <joint name="top_plate_joint" type="fixed">
    <parent link="base_link"/>
    <child link="top_plate_link"/>
    <origin rpy="0 0 0" xyz="0.0812 0 0.245"/>
  </joint>
  <!-- Top plate front link -->
  <joint name="top_plate_front_joint" type="fixed">
    <parent link="top_plate_link"/>
    <child link="top_plate_front_link"/>
    <origin rpy="0 0 0" xyz="0.36367 0 0.00639"/>
  </joint>
  <!-- Top plate rear link-->
  <joint name="top_plate_rear_joint" type="fixed">
    <parent link="top_plate_link"/>
    <child link="top_plate_rear_link"/>
    <origin rpy="0 0 0" xyz="-0.36633 0 0.00639"/>
  </joint>
  <link name="top_plate_front_link"/>
  <link name="top_plate_rear_link"/>
  <!-- <xacro:if value="$(arg laser_enabled)">

      <xacro:sick_lms1xx_mount prefix="base"/>

      <xacro:sick_lms1xx frame="base_laser" topic="scan" robot_namespace="$(arg robot_namespace)"/>

      <joint name="laser_mount_joint" type="fixed">
        <origin xyz="$(arg laser_xyz)" rpy="$(arg laser_rpy)" />
        <parent link="top_plate_link" />
        <child link="base_laser_mount" />
      </joint>

    </xacro:if> -->
  <!--
      top sensor arch; include this if we have realsense enabled
      keep this as a property to make it easier to add multiple conditions, should we need
      the top bar for any additional sensors in the future
    -->
  <!-- <xacro:property name="topbar_needed_realsense" value="$(arg realsense_enabled)" />
    <xacro:if value="${topbar_needed_realsense}">
      <xacro:sensor_arch prefix="" parent="top_plate_link">
        <origin xyz="-0.35 0 0.51" rpy="0 0 -3.14"/>
      </xacro:sensor_arch>
    </xacro:if> -->
  <ros2_control name="husky_hardware" type="system">
    <hardware>
      <plugin>husky_base/HuskyHardware</plugin>
      <plugin>fake_components/GenericSystem</plugin>
      <param name="hw_start_duration_sec">2.0</param>
      <param name="hw_stop_duration_sec">3.0</param>
      <param name="wheel_diameter">0.3302</param>
      <param name="max_accel">5.0</param>
      <param name="max_speed">1.0</param>
      <param name="polling_timeout">10.0</param>
      <param name="serial_port">/dev/prolific</param>
    </hardware>
    <joint name="front_left_wheel_joint">
      <command_interface name="velocity">
        <param name="min">-1</param>
        <param name="max">1</param>
      </command_interface>
      <state_interface name="position"/>
      <state_interface name="velocity"/>
    </joint>
    <joint name="rear_left_wheel_joint">
      <command_interface name="velocity">
        <param name="min">-1</param>
        <param name="max">1</param>
      </command_interface>
      <state_interface name="position"/>
      <state_interface name="velocity"/>
    </joint>
    <joint name="front_right_wheel_joint">
      <command_interface name="velocity">
        <param name="min">-1</param>
        <param name="max">1</param>
      </command_interface>
      <state_interface name="position"/>
      <state_interface name="velocity"/>
    </joint>
    <joint name="rear_right_wheel_joint">
      <command_interface name="velocity">
        <param name="min">-1</param>
        <param name="max">1</param>
      </command_interface>
      <state_interface name="position"/>
      <state_interface name="velocity"/>
    </joint>
  </ros2_control>
  <material name="aluminum">
    <color rgba="0.5 0.5 0.5 1"/>
  </material>
  <material name="plastic">
    <color rgba="0.1 0.1 0.1 1"/>
  </material>
  <!-- left/right |y| -->
  <!-- camera body, with origin at bottom screw mount -->
  <joint name="front_camera_joint" type="fixed">
    <origin rpy="0 0 0" xyz="0.43 0 0.15"/>
    <parent link="base_link"/>
    <child link="front_camera_bottom_screw_frame"/>
  </joint>
  <link name="front_camera_bottom_screw_frame"/>
  <joint name="front_camera_link_joint" type="fixed">
    <origin rpy="0 0 0" xyz="0.010600000000000002 0.0175 0.0125"/>
    <parent link="front_camera_bottom_screw_frame"/>
    <child link="front_camera_link"/>
  </joint>
  <link name="front_camera_link">
    <visual>
      <!-- the mesh origin is at front plate in between the two infrared camera axes -->
      <origin rpy="1.5707963267948966 0 1.5707963267948966" xyz="0.0043 -0.0175 0"/>
      <geometry>
        <mesh filename="/home/vaibhav/husky/husky_ws/install/realsense2_description/share/realsense2_description/meshes/d435.dae"/>
      </geometry>
    </visual>
    <collision>
      <origin rpy="0 0 0" xyz="0 -0.0175 0"/>
      <geometry>
        <box size="0.02505 0.09 0.025"/>
      </geometry>
    </collision>
    <inertial>
      <!-- The following are not reliable values, and should not be used for modeling -->
      <mass value="0.072"/>
      <origin xyz="0 0 0"/>
      <inertia ixx="0.003881243" ixy="0.0" ixz="0.0" iyy="0.000498940" iyz="0.0" izz="0.003879257"/>
    </inertial>
  </link>
  <!-- camera depth joints and links -->
  <joint name="front_camera_depth_joint" type="fixed">
    <origin rpy="0 0 0" xyz="0 0 0"/>
    <parent link="front_camera_link"/>
    <child link="front_camera_depth_frame"/>
  </joint>
  <link name="front_camera_depth_frame"/>
  <joint name="front_camera_depth_optical_joint" type="fixed">
    <origin rpy="-1.5707963267948966 0 -1.5707963267948966" xyz="0 0 0"/>
    <parent link="front_camera_depth_frame"/>
    <child link="front_camera_depth_optical_frame"/>
  </joint>
  <link name="front_camera_depth_optical_frame"/>
  <!-- camera left IR joints and links -->
  <joint name="front_camera_infra1_joint" type="fixed">
    <origin rpy="0 0 0" xyz="0 0.0 0"/>
    <parent link="front_camera_link"/>
    <child link="front_camera_infra1_frame"/>
  </joint>
  <link name="front_camera_infra1_frame"/>
  <joint name="front_camera_infra1_optical_joint" type="fixed">
    <origin rpy="-1.5707963267948966 0 -1.5707963267948966" xyz="0 0 0"/>
    <parent link="front_camera_infra1_frame"/>
    <child link="front_camera_infra1_optical_frame"/>
  </joint>
  <link name="front_camera_infra1_optical_frame"/>
  <!-- camera right IR joints and links -->
  <joint name="front_camera_infra2_joint" type="fixed">
    <origin rpy="0 0 0" xyz="0 -0.05 0"/>
    <parent link="front_camera_link"/>
    <child link="front_camera_infra2_frame"/>
  </joint>
  <link name="front_camera_infra2_frame"/>
  <joint name="front_camera_infra2_optical_joint" type="fixed">
    <origin rpy="-1.5707963267948966 0 -1.5707963267948966" xyz="0 0 0"/>
    <parent link="front_camera_infra2_frame"/>
    <child link="front_camera_infra2_optical_frame"/>
  </joint>
  <link name="front_camera_infra2_optical_frame"/>
  <!-- camera color joints and links -->
  <joint name="front_camera_color_joint" type="fixed">
    <origin rpy="0 0 0" xyz="0 0.015 0"/>
    <parent link="front_camera_link"/>
    <child link="front_camera_color_frame"/>
  </joint>
  <link name="front_camera_color_frame"/>
  <joint name="front_camera_color_optical_joint" type="fixed">
    <origin rpy="-1.5707963267948966 0 -1.5707963267948966" xyz="0 0 0"/>
    <parent link="front_camera_color_frame"/>
    <child link="front_camera_color_optical_frame"/>
  </joint>
  <link name="front_camera_color_optical_frame"/>
  <!-- camera body, with origin at bottom screw mount -->
  <joint name="rear_camera_joint" type="fixed">
    <origin rpy="0 0 3.141592653589793" xyz="-0.43 0 0.15"/>
    <parent link="base_link"/>
    <child link="rear_camera_bottom_screw_frame"/>
  </joint>
  <link name="rear_camera_bottom_screw_frame"/>
  <joint name="rear_camera_link_joint" type="fixed">
    <origin rpy="0 0 0" xyz="0.010600000000000002 0.0175 0.0125"/>
    <parent link="rear_camera_bottom_screw_frame"/>
    <child link="rear_camera_link"/>
  </joint>
  <link name="rear_camera_link">
    <visual>
      <!-- the mesh origin is at front plate in between the two infrared camera axes -->
      <origin rpy="1.5707963267948966 0 1.5707963267948966" xyz="0.0043 -0.0175 0"/>
      <geometry>
        <mesh filename="/home/vaibhav/husky/husky_ws/install/realsense2_description/share/realsense2_description/meshes/d435.dae"/>
      </geometry>
    </visual>
    <collision>
      <origin rpy="0 0 0" xyz="0 -0.0175 0"/>
      <geometry>
        <box size="0.02505 0.09 0.025"/>
      </geometry>
    </collision>
    <inertial>
      <!-- The following are not reliable values, and should not be used for modeling -->
      <mass value="0.072"/>
      <origin xyz="0 0 0"/>
      <inertia ixx="0.003881243" ixy="0.0" ixz="0.0" iyy="0.000498940" iyz="0.0" izz="0.003879257"/>
    </inertial>
  </link>
  <!-- camera depth joints and links -->
  <joint name="rear_camera_depth_joint" type="fixed">
    <origin rpy="0 0 0" xyz="0 0 0"/>
    <parent link="rear_camera_link"/>
    <child link="rear_camera_depth_frame"/>
  </joint>
  <link name="rear_camera_depth_frame"/>
  <joint name="rear_camera_depth_optical_joint" type="fixed">
    <origin rpy="-1.5707963267948966 0 -1.5707963267948966" xyz="0 0 0"/>
    <parent link="rear_camera_depth_frame"/>
    <child link="rear_camera_depth_optical_frame"/>
  </joint>
  <link name="rear_camera_depth_optical_frame"/>
  <!-- camera left IR joints and links -->
  <joint name="rear_camera_infra1_joint" type="fixed">
    <origin rpy="0 0 0" xyz="0 0.0 0"/>
    <parent link="rear_camera_link"/>
    <child link="rear_camera_infra1_frame"/>
  </joint>
  <link name="rear_camera_infra1_frame"/>
  <joint name="rear_camera_infra1_optical_joint" type="fixed">
    <origin rpy="-1.5707963267948966 0 -1.5707963267948966" xyz="0 0 0"/>
    <parent link="rear_camera_infra1_frame"/>
    <child link="rear_camera_infra1_optical_frame"/>
  </joint>
  <link name="rear_camera_infra1_optical_frame"/>
  <!-- camera right IR joints and links -->
  <joint name="rear_camera_infra2_joint" type="fixed">
    <origin rpy="0 0 0" xyz="0 -0.05 0"/>
    <parent link="rear_camera_link"/>
    <child link="rear_camera_infra2_frame"/>
  </joint>
  <link name="rear_camera_infra2_frame"/>
  <joint name="rear_camera_infra2_optical_joint" type="fixed">
    <origin rpy="-1.5707963267948966 0 -1.5707963267948966" xyz="0 0 0"/>
    <parent link="rear_camera_infra2_frame"/>
    <child link="rear_camera_infra2_optical_frame"/>
  </joint>
  <link name="rear_camera_infra2_optical_frame"/>
  <!-- camera color joints and links -->
  <joint name="rear_camera_color_joint" type="fixed">
    <origin rpy="0 0 0" xyz="0 0.015 0"/>
    <parent link="rear_camera_link"/>
    <child link="rear_camera_color_frame"/>
  </joint>
  <link name="rear_camera_color_frame"/>
  <joint name="rear_camera_color_optical_joint" type="fixed">
    <origin rpy="-1.5707963267948966 0 -1.5707963267948966" xyz="0 0 0"/>
    <parent link="rear_camera_color_frame"/>
    <child link="rear_camera_color_optical_frame"/>
  </joint>
  <link name="rear_camera_color_optical_frame"/>
  <!-- camera body, with origin at bottom screw mount -->
  <joint name="left_camera_joint" type="fixed">
    <origin rpy="0 0 1.5707963267948966" xyz="0 0.28 0.15"/>
    <parent link="base_link"/>
    <child link="left_camera_bottom_screw_frame"/>
  </joint>
  <link name="left_camera_bottom_screw_frame"/>
  <joint name="left_camera_link_joint" type="fixed">
    <origin rpy="0 0 0" xyz="0.010600000000000002 0.0175 0.0125"/>
    <parent link="left_camera_bottom_screw_frame"/>
    <child link="left_camera_link"/>
  </joint>
  <link name="left_camera_link">
    <visual>
      <!-- the mesh origin is at front plate in between the two infrared camera axes -->
      <origin rpy="1.5707963267948966 0 1.5707963267948966" xyz="0.0043 -0.0175 0"/>
      <geometry>
        <mesh filename="/home/vaibhav/husky/husky_ws/install/realsense2_description/share/realsense2_description/meshes/d435.dae"/>
      </geometry>
    </visual>
    <collision>
      <origin rpy="0 0 0" xyz="0 -0.0175 0"/>
      <geometry>
        <box size="0.02505 0.09 0.025"/>
      </geometry>
    </collision>
    <inertial>
      <!-- The following are not reliable values, and should not be used for modeling -->
      <mass value="0.072"/>
      <origin xyz="0 0 0"/>
      <inertia ixx="0.003881243" ixy="0.0" ixz="0.0" iyy="0.000498940" iyz="0.0" izz="0.003879257"/>
    </inertial>
  </link>
  <!-- camera depth joints and links -->
  <joint name="left_camera_depth_joint" type="fixed">
    <origin rpy="0 0 0" xyz="0 0 0"/>
    <parent link="left_camera_link"/>
    <child link="left_camera_depth_frame"/>
  </joint>
  <link name="left_camera_depth_frame"/>
  <joint name="left_camera_depth_optical_joint" type="fixed">
    <origin rpy="-1.5707963267948966 0 -1.5707963267948966" xyz="0 0 0"/>
    <parent link="left_camera_depth_frame"/>
    <child link="left_camera_depth_optical_frame"/>
  </joint>
  <link name="left_camera_depth_optical_frame"/>
  <!-- camera left IR joints and links -->
  <joint name="left_camera_infra1_joint" type="fixed">
    <origin rpy="0 0 0" xyz="0 0.0 0"/>
    <parent link="left_camera_link"/>
    <child link="left_camera_infra1_frame"/>
  </joint>
  <link name="left_camera_infra1_frame"/>
  <joint name="left_camera_infra1_optical_joint" type="fixed">
    <origin rpy="-1.5707963267948966 0 -1.5707963267948966" xyz="0 0 0"/>
    <parent link="left_camera_infra1_frame"/>
    <child link="left_camera_infra1_optical_frame"/>
  </joint>
  <link name="left_camera_infra1_optical_frame"/>
  <!-- camera right IR joints and links -->
  <joint name="left_camera_infra2_joint" type="fixed">
    <origin rpy="0 0 0" xyz="0 -0.05 0"/>
    <parent link="left_camera_link"/>
    <child link="left_camera_infra2_frame"/>
  </joint>
  <link name="left_camera_infra2_frame"/>
  <joint name="left_camera_infra2_optical_joint" type="fixed">
    <origin rpy="-1.5707963267948966 0 -1.5707963267948966" xyz="0 0 0"/>
    <parent link="left_camera_infra2_frame"/>
    <child link="left_camera_infra2_optical_frame"/>
  </joint>
  <link name="left_camera_infra2_optical_frame"/>
  <!-- camera color joints and links -->
  <joint name="left_camera_color_joint" type="fixed">
    <origin rpy="0 0 0" xyz="0 0.015 0"/>
    <parent link="left_camera_link"/>
    <child link="left_camera_color_frame"/>
  </joint>
  <link name="left_camera_color_frame"/>
  <joint name="left_camera_color_optical_joint" type="fixed">
    <origin rpy="-1.5707963267948966 0 -1.5707963267948966" xyz="0 0 0"/>
    <parent link="left_camera_color_frame"/>
    <child link="left_camera_color_optical_frame"/>
  </joint>
  <link name="left_camera_color_optical_frame"/>
  <!-- camera body, with origin at bottom screw mount -->
  <joint name="right_camera_joint" type="fixed">
    <origin rpy="0 0 -1.5707963267948966" xyz="0 -0.28 0.15"/>
    <parent link="base_link"/>
    <child link="right_camera_bottom_screw_frame"/>
  </joint>
  <link name="right_camera_bottom_screw_frame"/>
  <joint name="right_camera_link_joint" type="fixed">
    <origin rpy="0 0 0" xyz="0.010600000000000002 0.0175 0.0125"/>
    <parent link="right_camera_bottom_screw_frame"/>
    <child link="right_camera_link"/>
  </joint>
  <link name="right_camera_link">
    <visual>
      <!-- the mesh origin is at front plate in between the two infrared camera axes -->
      <origin rpy="1.5707963267948966 0 1.5707963267948966" xyz="0.0043 -0.0175 0"/>
      <geometry>
        <mesh filename="/home/vaibhav/husky/husky_ws/install/realsense2_description/share/realsense2_description/meshes/d435.dae"/>
      </geometry>
    </visual>
    <collision>
      <origin rpy="0 0 0" xyz="0 -0.0175 0"/>
      <geometry>
        <box size="0.02505 0.09 0.025"/>
      </geometry>
    </collision>
    <inertial>
      <!-- The following are not reliable values, and should not be used for modeling -->
      <mass value="0.072"/>
      <origin xyz="0 0 0"/>
      <inertia ixx="0.003881243" ixy="0.0" ixz="0.0" iyy="0.000498940" iyz="0.0" izz="0.003879257"/>
    </inertial>
  </link>
  <!-- camera depth joints and links -->
  <joint name="right_camera_depth_joint" type="fixed">
    <origin rpy="0 0 0" xyz="0 0 0"/>
    <parent link="right_camera_link"/>
    <child link="right_camera_depth_frame"/>
  </joint>
  <link name="right_camera_depth_frame"/>
  <joint name="right_camera_depth_optical_joint" type="fixed">
    <origin rpy="-1.5707963267948966 0 -1.5707963267948966" xyz="0 0 0"/>
    <parent link="right_camera_depth_frame"/>
    <child link="right_camera_depth_optical_frame"/>
  </joint>
  <link name="right_camera_depth_optical_frame"/>
  <!-- camera left IR joints and links -->
  <joint name="right_camera_infra1_joint" type="fixed">
    <origin rpy="0 0 0" xyz="0 0.0 0"/>
    <parent link="right_camera_link"/>
    <child link="right_camera_infra1_frame"/>
  </joint>
  <link name="right_camera_infra1_frame"/>
  <joint name="right_camera_infra1_optical_joint" type="fixed">
    <origin rpy="-1.5707963267948966 0 -1.5707963267948966" xyz="0 0 0"/>
    <parent link="right_camera_infra1_frame"/>
    <child link="right_camera_infra1_optical_frame"/>
  </joint>
  <link name="right_camera_infra1_optical_frame"/>
  <!-- camera right IR joints and links -->
  <joint name="right_camera_infra2_joint" type="fixed">
    <origin rpy="0 0 0" xyz="0 -0.05 0"/>
    <parent link="right_camera_link"/>
    <child link="right_camera_infra2_frame"/>
  </joint>
  <link name="right_camera_infra2_frame"/>
  <joint name="right_camera_infra2_optical_joint" type="fixed">
    <origin rpy="-1.5707963267948966 0 -1.5707963267948966" xyz="0 0 0"/>
    <parent link="right_camera_infra2_frame"/>
    <child link="right_camera_infra2_optical_frame"/>
  </joint>
  <link name="right_camera_infra2_optical_frame"/>
  <!-- camera color joints and links -->
  <joint name="right_camera_color_joint" type="fixed">
    <origin rpy="0 0 0" xyz="0 0.015 0"/>
    <parent link="right_camera_link"/>
    <child link="right_camera_color_frame"/>
  </joint>
  <link name="right_camera_color_frame"/>
  <joint name="right_camera_color_optical_joint" type="fixed">
    <origin rpy="-1.5707963267948966 0 -1.5707963267948966" xyz="0 0 0"/>
    <parent link="right_camera_color_frame"/>
    <child link="right_camera_color_optical_frame"/>
  </joint>
  <link name="right_camera_color_optical_frame"/>
</robot>
